<?xml version="1.0" encoding="UTF-8"?>
<robot generator="Robot 6.0.2 (Python 3.11.1 on win32)" generated="20230201 15:59:30.013" rpa="false" schemaversion="3">
<suite id="s1" name="Invalid Login" source="C:\Users\40032486\project1\1__login_suite\01__invalid_login.robot">
<test id="s1-t1" name="TC1" line="14">
<status status="FAIL" starttime="20230201 15:59:30.322" endtime="20230201 15:59:30.324">Test contains no keywords.</status>
</test>
<doc>This file contains invalid logins</doc>
<status status="FAIL" starttime="20230201 15:59:30.017" endtime="20230201 15:59:30.326"/>
</suite>
<statistics>
<total>
<stat pass="0" fail="1" skip="0">All Tests</stat>
</total>
<tag>
</tag>
<suite>
<stat pass="0" fail="1" skip="0" id="s1" name="Invalid Login">Invalid Login</stat>
</suite>
</statistics>
<errors>
<msg timestamp="20230201 15:59:30.318" level="ERROR">[ DataDriver ] Error in robot file:
  File "C:\Users\40032486\project1\1__login_suite\01__invalid_login.robot", line 0</msg>
<msg timestamp="20230201 15:59:30.318" level="ERROR">In source file:
  File "../test_data/project.xlsx", line 0</msg>
<msg timestamp="20230201 15:59:30.321" level="ERROR">Calling method '_start_suite' of listener 'DataDriver' failed: FileNotFoundError: File attribute was not a full path. Tried to find C:\Users\40032486\project1\1__login_suite\../test_data/project.xlsx but file does not exist.</msg>
</errors>
</robot>
